<sdf version='1.7'>
  <world name='default'>
    <light name='sun' type='directional'>
      <cast_shadows>1</cast_shadows>
      <pose>0 0 10 0 -0 0</pose>
      <diffuse>0.8 0.8 0.8 1</diffuse>
      <specular>0.2 0.2 0.2 1</specular>
      <attenuation>
        <range>1000</range>
        <constant>0.9</constant>
        <linear>0.01</linear>
        <quadratic>0.001</quadratic>
      </attenuation>
      <direction>-0.5 0.1 -0.9</direction>
      <spot>
        <inner_angle>0</inner_angle>
        <outer_angle>0</outer_angle>
        <falloff>0</falloff>
      </spot>
    </light>
    <model name='ground_plane'>
      <static>1</static>
      <link name='link'>
        <collision name='collision'>
          <geometry>
            <plane>
              <normal>0 0 1</normal>
              <size>100 100</size>
            </plane>
          </geometry>
          <surface>
            <friction>
              <ode>
                <mu>100</mu>
                <mu2>50</mu2>
              </ode>
              <torsional>
                <ode/>
              </torsional>
            </friction>
            <contact>
              <ode/>
            </contact>
            <bounce/>
          </surface>
          <max_contacts>10</max_contacts>
        </collision>
        <visual name='visual'>
          <cast_shadows>0</cast_shadows>
          <geometry>
            <plane>
              <normal>0 0 1</normal>
              <size>100 100</size>
            </plane>
          </geometry>
          <material>
            <script>
              <uri>file://media/materials/scripts/gazebo.material</uri>
              <name>Gazebo/Grey</name>
            </script>
          </material>
        </visual>
        <self_collide>0</self_collide>
        <enable_wind>0</enable_wind>
        <kinematic>0</kinematic>
      </link>
    </model>
    <gravity>0 0 -9.8</gravity>
    <magnetic_field>6e-06 2.3e-05 -4.2e-05</magnetic_field>
    <atmosphere type='adiabatic'/>
    <physics type='ode'>
      <max_step_size>0.001</max_step_size>
      <real_time_factor>1</real_time_factor>
      <real_time_update_rate>1000</real_time_update_rate>
    </physics>
    <scene>
      <ambient>0.4 0.4 0.4 1</ambient>
      <background>0.7 0.7 0.7 1</background>
      <shadows>1</shadows>
    </scene>
    <audio>
      <device>default</device>
    </audio>
    <wind/>
    <spherical_coordinates>
      <surface_model>EARTH_WGS84</surface_model>
      <latitude_deg>0</latitude_deg>
      <longitude_deg>0</longitude_deg>
      <elevation>0</elevation>
      <heading_deg>0</heading_deg>
    </spherical_coordinates>
    <model name='rover' xmlns:gazebo='http://gazebosim.org/schema'>
      <link name='chassis'>
        <visual name='chassis_visual'>
          <geometry>
            <mesh>
              <uri>/home/gen/Downloads/RoverArmv3/RoverArm/Rover/meshes/chassis.dae</uri>
            </mesh>
          </geometry>
          <material>
            <ambient>0.2 0.4 0.8 1</ambient>
            <diffuse>0.3 0.5 0.9 1</diffuse>
            <specular>0.9 0.9 0.9 1</specular>
            <emissive>0 0 0 1</emissive>
          </material>
        </visual>
        <collision name='chassis_collision'>
          <geometry>
            <mesh>
              <uri>/home/gen/Downloads/RoverArmv3/RoverArm/Rover/meshes/chassis_collision.dae</uri>
            </mesh>
          </geometry>
          <max_contacts>10</max_contacts>
          <surface>
            <contact>
              <ode/>
            </contact>
            <bounce/>
            <friction>
              <torsional>
                <ode/>
              </torsional>
              <ode/>
            </friction>
          </surface>
        </collision>
        <inertial>
          <mass>100</mass>
          <inertia>
            <ixx>0.2399</ixx>
            <iyy>0.2399</iyy>
            <izz>0.417</izz>
            <ixy>0</ixy>
            <ixz>0</ixz>
            <iyz>0</iyz>
          </inertia>
          <pose>0 0 0 0 -0 0</pose>
        </inertial>
        <self_collide>0</self_collide>
        <enable_wind>0</enable_wind>
        <kinematic>0</kinematic>
      </link>
      <link name='front_right_wheel'>
        <pose>0.172227 -0.160823 -0.092849 0 -0 0</pose>
        <visual name='front_right_wheel_visual'>
          <geometry>
            <mesh>
              <uri>/home/gen/Downloads/RoverArmv3/RoverArm/Rover/meshes/front_right_wheel.dae</uri>
            </mesh>
          </geometry>
          <material>
            <ambient>0.1 0.1 0.1 1</ambient>
            <diffuse>0.2 0.2 0.2 1</diffuse>
            <specular>0.1 0.1 0.1 1</specular>
            <emissive>0 0 0 1</emissive>
          </material>
        </visual>
        <collision name='front_right_wheel_collision'>
          <pose>0 0 0 1.5708 -0 0</pose>
          <geometry>
            <cylinder>
              <radius>0.052983</radius>
              <length>0.0662</length>
            </cylinder>
          </geometry>
          <surface>
            <friction>
              <ode>
                <mu>1.2</mu>
                <mu2>0.3</mu2>
                <fdir1>0 1 0</fdir1>
              </ode>
              <torsional>
                <ode/>
              </torsional>
            </friction>
            <contact>
              <ode/>
            </contact>
            <bounce/>
          </surface>
          <max_contacts>10</max_contacts>
        </collision>
        <inertial>
          <mass>5</mass>
          <inertia>
            <ixx>0.0021</ixx>
            <iyy>0.0028</iyy>
            <izz>0.0021</izz>
            <ixy>0</ixy>
            <ixz>0</ixz>
            <iyz>0</iyz>
          </inertia>
          <pose>0 0 0 0 -0 0</pose>
        </inertial>
        <self_collide>0</self_collide>
        <enable_wind>0</enable_wind>
        <kinematic>0</kinematic>
      </link>
      <link name='front_left_wheel'>
        <pose>0.172227 0.160851 -0.092849 0 -0 0</pose>
        <visual name='front_left_wheel_visual'>
          <geometry>
            <mesh>
              <uri>/home/gen/Downloads/RoverArmv3/RoverArm/Rover/meshes/front_left_wheel.dae</uri>
            </mesh>
          </geometry>
          <material>
            <ambient>0.1 0.1 0.1 1</ambient>
            <diffuse>0.2 0.2 0.2 1</diffuse>
            <specular>0.1 0.1 0.1 1</specular>
            <emissive>0 0 0 1</emissive>
          </material>
        </visual>
        <collision name='front_left_wheel_collision'>
          <pose>0 0 0 1.5708 -0 0</pose>
          <geometry>
            <cylinder>
              <radius>0.052983</radius>
              <length>0.0662</length>
            </cylinder>
          </geometry>
          <surface>
            <friction>
              <ode>
                <mu>1.2</mu>
                <mu2>0.3</mu2>
                <fdir1>0 1 0</fdir1>
              </ode>
              <torsional>
                <ode/>
              </torsional>
            </friction>
            <contact>
              <ode/>
            </contact>
            <bounce/>
          </surface>
          <max_contacts>10</max_contacts>
        </collision>
        <inertial>
          <mass>5</mass>
          <inertia>
            <ixx>0.0021</ixx>
            <iyy>0.0028</iyy>
            <izz>0.0021</izz>
            <ixy>0</ixy>
            <ixz>0</ixz>
            <iyz>0</iyz>
          </inertia>
          <pose>0 0 0 0 -0 0</pose>
        </inertial>
        <self_collide>0</self_collide>
        <enable_wind>0</enable_wind>
        <kinematic>0</kinematic>
      </link>
      <link name='rear_left_wheel'>
        <pose>-0.172255 0.160852 -0.092849 0 -0 0</pose>
        <visual name='rear_left_wheel_visual'>
          <geometry>
            <mesh>
              <uri>/home/gen/Downloads/RoverArmv3/RoverArm/Rover/meshes/back_left_wheel.dae</uri>
            </mesh>
          </geometry>
          <material>
            <ambient>0.1 0.1 0.1 1</ambient>
            <diffuse>0.2 0.2 0.2 1</diffuse>
            <specular>0.1 0.1 0.1 1</specular>
            <emissive>0 0 0 1</emissive>
          </material>
        </visual>
        <collision name='back_left_wheel_collision'>
          <pose>0 0 0 1.5708 -0 0</pose>
          <geometry>
            <cylinder>
              <radius>0.052983</radius>
              <length>0.0662</length>
            </cylinder>
          </geometry>
          <surface>
            <friction>
              <ode>
                <mu>1.2</mu>
                <mu2>0.3</mu2>
                <fdir1>0 1 0</fdir1>
              </ode>
              <torsional>
                <ode/>
              </torsional>
            </friction>
            <contact>
              <ode/>
            </contact>
            <bounce/>
          </surface>
          <max_contacts>10</max_contacts>
        </collision>
        <inertial>
          <mass>5</mass>
          <inertia>
            <ixx>0.0021</ixx>
            <iyy>0.0028</iyy>
            <izz>0.0021</izz>
            <ixy>0</ixy>
            <ixz>0</ixz>
            <iyz>0</iyz>
          </inertia>
          <pose>0 0 0 0 -0 0</pose>
        </inertial>
        <self_collide>0</self_collide>
        <enable_wind>0</enable_wind>
        <kinematic>0</kinematic>
      </link>
      <link name='rear_right_wheel'>
        <pose>-0.172255 -0.160831 -0.092849 0 -0 0</pose>
        <visual name='back_right_wheel_visual'>
          <geometry>
            <mesh>
              <uri>/home/gen/Downloads/RoverArmv3/RoverArm/Rover/meshes/back_right_wheel.dae</uri>
            </mesh>
          </geometry>
          <material>
            <ambient>0.1 0.1 0.1 1</ambient>
            <diffuse>0.2 0.2 0.2 1</diffuse>
            <specular>0.1 0.1 0.1 1</specular>
            <emissive>0 0 0 1</emissive>
          </material>
        </visual>
        <collision name='collision'>
          <pose>0 0 0 1.5708 -0 0</pose>
          <geometry>
            <cylinder>
              <radius>0.052983</radius>
              <length>0.0662</length>
            </cylinder>
          </geometry>
          <surface>
            <friction>
              <ode>
                <mu>1.2</mu>
                <mu2>0.3</mu2>
                <fdir1>0 1 0</fdir1>
              </ode>
              <torsional>
                <ode/>
              </torsional>
            </friction>
            <contact>
              <ode/>
            </contact>
            <bounce/>
          </surface>
          <max_contacts>10</max_contacts>
        </collision>
        <inertial>
          <mass>5</mass>
          <inertia>
            <ixx>0.0021</ixx>
            <iyy>0.0028</iyy>
            <izz>0.0021</izz>
            <ixy>0</ixy>
            <ixz>0</ixz>
            <iyz>0</iyz>
          </inertia>
          <pose>0 0 0 0 -0 0</pose>
        </inertial>
        <self_collide>0</self_collide>
        <enable_wind>0</enable_wind>
        <kinematic>0</kinematic>
      </link>
      <joint name='front_left_wheel_joint' type='revolute'>
        <parent>chassis</parent>
        <child>front_left_wheel</child>
        <axis>
          <xyz>0 1 0</xyz>
          <limit>
            <lower>-1.79769e+308</lower>
            <upper>1.79769e+308</upper>
          </limit>
          <dynamics>
            <spring_reference>0</spring_reference>
            <spring_stiffness>0</spring_stiffness>
          </dynamics>
        </axis>
      </joint>
      <joint name='front_right_wheel_joint' type='revolute'>
        <parent>chassis</parent>
        <child>front_right_wheel</child>
        <axis>
          <xyz>0 1 0</xyz>
          <limit>
            <lower>-1.79769e+308</lower>
            <upper>1.79769e+308</upper>
          </limit>
          <dynamics>
            <spring_reference>0</spring_reference>
            <spring_stiffness>0</spring_stiffness>
          </dynamics>
        </axis>
      </joint>
      <joint name='rear_left_wheel_joint' type='revolute'>
        <parent>chassis</parent>
        <child>rear_left_wheel</child>
        <axis>
          <xyz>0 1 0</xyz>
          <limit>
            <lower>-1.79769e+308</lower>
            <upper>1.79769e+308</upper>
          </limit>
          <dynamics>
            <spring_reference>0</spring_reference>
            <spring_stiffness>0</spring_stiffness>
          </dynamics>
        </axis>
      </joint>
      <joint name='rear_right_wheel_joint' type='revolute'>
        <parent>chassis</parent>
        <child>rear_right_wheel</child>
        <axis>
          <xyz>0 1 0</xyz>
          <limit>
            <lower>-1.79769e+308</lower>
            <upper>1.79769e+308</upper>
          </limit>
          <dynamics>
            <spring_reference>0</spring_reference>
            <spring_stiffness>0</spring_stiffness>
          </dynamics>
        </axis>
      </joint>
      <frame name='panda::__model__' attached_to='panda::panda_link0'>
        <pose relative_to='__model__'>0 0 0.05 0 -0 0</pose>
      </frame>
      <link name='panda::panda_link0'>
        <visual name='panda_link0_visual'>
          <geometry>
            <mesh>
              <uri>meshes/visual/link0.dae</uri>
            </mesh>
          </geometry>
        </visual>
        <collision name='panda_link0_collision'>
          <geometry>
            <mesh>
              <uri>meshes/collision/link0.stl</uri>
            </mesh>
          </geometry>
          <surface>
            <friction>
              <ode>
                <mu>1.05</mu>
                <mu2>1.05</mu2>
              </ode>
              <torsional>
                <ode/>
              </torsional>
            </friction>
            <contact>
              <ode/>
            </contact>
            <bounce/>
          </surface>
          <max_contacts>10</max_contacts>
        </collision>
        <inertial>
          <pose>-0.025566 -2.9e-05 0.057332 0 -0 0</pose>
          <mass>2.81427</mass>
          <inertia>
            <ixx>0.00753906</ixx>
            <iyy>0.010508</iyy>
            <izz>0.00986493</izz>
            <ixy>-1.50531e-05</ixy>
            <ixz>-0.00121443</ixz>
            <iyz>1.04348e-05</iyz>
          </inertia>
        </inertial>
        <pose relative_to='panda::__model__'>0 0 0 0 -0 0</pose>
        <self_collide>0</self_collide>
        <enable_wind>0</enable_wind>
        <kinematic>0</kinematic>
      </link>
      <link name='panda::panda_link1'>
        <pose relative_to='panda::panda_joint1'>0 0 0 0 -0 0</pose>
        <visual name='panda_link1_visual'>
          <geometry>
            <mesh>
              <uri>meshes/visual/link1.dae</uri>
            </mesh>
          </geometry>
        </visual>
        <collision name='panda_link1_collision'>
          <geometry>
            <mesh>
              <uri>meshes/collision/link1.stl</uri>
            </mesh>
          </geometry>
          <surface>
            <friction>
              <ode>
                <mu>1.05</mu>
                <mu2>1.05</mu2>
              </ode>
              <torsional>
                <ode/>
              </torsional>
            </friction>
            <contact>
              <ode/>
            </contact>
            <bounce/>
          </surface>
          <max_contacts>10</max_contacts>
        </collision>
        <inertial>
          <pose>-0 -0.032496 -0.067582 0 -0 0</pose>
          <mass>2.64332</mass>
          <inertia>
            <ixx>0.0174051</ixx>
            <iyy>0.0153521</iyy>
            <izz>0.00598789</izz>
            <ixy>-8.68799e-09</ixy>
            <ixz>-1.62778e-08</ixz>
            <iyz>0.00451086</iyz>
          </inertia>
        </inertial>
        <self_collide>0</self_collide>
        <enable_wind>0</enable_wind>
        <kinematic>0</kinematic>
      </link>
      <link name='panda::panda_link2'>
        <pose relative_to='panda::panda_joint2'>0 0 0 0 -0 0</pose>
        <visual name='panda_link2_visual'>
          <geometry>
            <mesh>
              <uri>meshes/visual/link2.dae</uri>
            </mesh>
          </geometry>
        </visual>
        <collision name='panda_link2_collision'>
          <geometry>
            <mesh>
              <uri>meshes/collision/link2.stl</uri>
            </mesh>
          </geometry>
          <surface>
            <friction>
              <ode>
                <mu>1.05</mu>
                <mu2>1.05</mu2>
              </ode>
              <torsional>
                <ode/>
              </torsional>
            </friction>
            <contact>
              <ode/>
            </contact>
            <bounce/>
          </surface>
          <max_contacts>10</max_contacts>
        </collision>
        <inertial>
          <pose>0 -0.06861 0.032229 0 -0 0</pose>
          <mass>2.66528</mass>
          <inertia>
            <ixx>0.0177869</ixx>
            <iyy>0.00604413</iyy>
            <izz>0.015711</izz>
            <ixy>8.70636e-08</ixy>
            <ixz>3.75207e-08</ixz>
            <iyz>-0.00459949</iyz>
          </inertia>
        </inertial>
        <self_collide>0</self_collide>
        <enable_wind>0</enable_wind>
        <kinematic>0</kinematic>
      </link>
      <link name='panda::panda_link3'>
        <pose relative_to='panda::panda_joint3'>0 0 0 0 -0 0</pose>
        <visual name='panda_link3_visual'>
          <geometry>
            <mesh>
              <uri>meshes/visual/link3.dae</uri>
            </mesh>
          </geometry>
        </visual>
        <collision name='panda_link3_collision'>
          <geometry>
            <mesh>
              <uri>meshes/collision/link3.stl</uri>
            </mesh>
          </geometry>
          <surface>
            <friction>
              <ode>
                <mu>1.05</mu>
                <mu2>1.05</mu2>
              </ode>
              <torsional>
                <ode/>
              </torsional>
            </friction>
            <contact>
              <ode/>
            </contact>
            <bounce/>
          </surface>
          <max_contacts>10</max_contacts>
        </collision>
        <inertial>
          <pose>0.046989 0.031637 -0.031704 0 -0 0</pose>
          <mass>2.32937</mass>
          <inertia>
            <ixx>0.00754968</ixx>
            <iyy>0.00968068</iyy>
            <izz>0.00794456</izz>
            <ixy>-0.00243205</ixy>
            <ixz>-0.00325082</ixz>
            <iyz>-0.00213163</iyz>
          </inertia>
        </inertial>
        <self_collide>0</self_collide>
        <enable_wind>0</enable_wind>
        <kinematic>0</kinematic>
      </link>
      <link name='panda::panda_link4'>
        <pose relative_to='panda::panda_joint4'>0 0 0 0 -0 0</pose>
        <visual name='panda_link4_visual'>
          <geometry>
            <mesh>
              <uri>meshes/visual/link4.dae</uri>
            </mesh>
          </geometry>
        </visual>
        <collision name='panda_link4_collision'>
          <geometry>
            <mesh>
              <uri>meshes/collision/link4.stl</uri>
            </mesh>
          </geometry>
          <surface>
            <friction>
              <ode>
                <mu>1.05</mu>
                <mu2>1.05</mu2>
              </ode>
              <torsional>
                <ode/>
              </torsional>
            </friction>
            <contact>
              <ode/>
            </contact>
            <bounce/>
          </surface>
          <max_contacts>10</max_contacts>
        </collision>
        <inertial>
          <pose>-0.036051 0.033707 0.031902 0 -0 0</pose>
          <mass>2.31048</mass>
          <inertia>
            <ixx>0.00776457</ixx>
            <iyy>0.00801578</iyy>
            <izz>0.00995588</izz>
            <ixy>0.00337148</ixy>
            <ixz>-0.00234362</ixz>
            <iyz>0.00229175</iyz>
          </inertia>
        </inertial>
        <self_collide>0</self_collide>
        <enable_wind>0</enable_wind>
        <kinematic>0</kinematic>
      </link>
      <link name='panda::panda_link5'>
        <pose relative_to='panda::panda_joint5'>0 0 0 0 -0 0</pose>
        <visual name='panda_link5_visual'>
          <geometry>
            <mesh>
              <uri>meshes/visual/link5.dae</uri>
            </mesh>
          </geometry>
        </visual>
        <collision name='panda_link5_collision'>
          <geometry>
            <mesh>
              <uri>meshes/collision/link5.stl</uri>
            </mesh>
          </geometry>
          <surface>
            <friction>
              <ode>
                <mu>1.05</mu>
                <mu2>1.05</mu2>
              </ode>
              <torsional>
                <ode/>
              </torsional>
            </friction>
            <contact>
              <ode/>
            </contact>
            <bounce/>
          </surface>
          <max_contacts>10</max_contacts>
        </collision>
        <inertial>
          <pose>-6e-06 0.061043 -0.104176 0 -0 0</pose>
          <mass>2.62264</mass>
          <inertia>
            <ixx>0.0290705</ixx>
            <iyy>0.0276385</iyy>
            <izz>0.00425111</izz>
            <ixy>6.20874e-07</ixy>
            <ixz>-1.00592e-05</ixz>
            <iyz>-0.00742431</iyz>
          </inertia>
        </inertial>
        <self_collide>0</self_collide>
        <enable_wind>0</enable_wind>
        <kinematic>0</kinematic>
      </link>
      <link name='panda::panda_link6'>
        <pose relative_to='panda::panda_joint6'>0 0 0 0 -0 0</pose>
        <visual name='panda_link6_visual'>
          <geometry>
            <mesh>
              <uri>meshes/visual/link6.dae</uri>
            </mesh>
          </geometry>
        </visual>
        <collision name='panda_link6_collision'>
          <geometry>
            <mesh>
              <uri>meshes/collision/link6.stl</uri>
            </mesh>
          </geometry>
          <surface>
            <friction>
              <ode>
                <mu>1.05</mu>
                <mu2>1.05</mu2>
              </ode>
              <torsional>
                <ode/>
              </torsional>
            </friction>
            <contact>
              <ode/>
            </contact>
            <bounce/>
          </surface>
          <max_contacts>10</max_contacts>
        </collision>
        <inertial>
          <pose>0.051051 0.009108 0.010634 0 -0 0</pose>
          <mass>1.50258</mass>
          <inertia>
            <ixx>0.00294056</ixx>
            <iyy>0.00392105</iyy>
            <izz>0.00541156</izz>
            <ixy>-0.000423911</ixy>
            <ixz>0.000610008</ixz>
            <iyz>0.000126475</iyz>
          </inertia>
        </inertial>
        <self_collide>0</self_collide>
        <enable_wind>0</enable_wind>
        <kinematic>0</kinematic>
      </link>
      <link name='panda::panda_link7'>
        <pose relative_to='panda::panda_joint7'>0 0 0 0 -0 0</pose>
        <visual name='panda_link7_visual'>
          <geometry>
            <mesh>
              <uri>meshes/visual/link7.dae</uri>
            </mesh>
          </geometry>
        </visual>
        <collision name='panda_link7_collision'>
          <geometry>
            <mesh>
              <uri>meshes/collision/link7.stl</uri>
            </mesh>
          </geometry>
          <surface>
            <friction>
              <ode>
                <mu>1.05</mu>
                <mu2>1.05</mu2>
              </ode>
              <torsional>
                <ode/>
              </torsional>
            </friction>
            <contact>
              <ode/>
            </contact>
            <bounce/>
          </surface>
          <max_contacts>10</max_contacts>
        </collision>
        <inertial>
          <pose>0.01097 0.010797 0.065041 0 -0 0</pose>
          <mass>0.523767</mass>
          <inertia>
            <ixx>0.000862147</ixx>
            <iyy>0.00086131</iyy>
            <izz>0.000696114</izz>
            <ixy>-0.000118711</ixy>
            <ixz>3.8666e-05</ixz>
            <iyz>-9.05784e-05</iyz>
          </inertia>
        </inertial>
        <self_collide>0</self_collide>
        <enable_wind>0</enable_wind>
        <kinematic>0</kinematic>
      </link>
      <joint name='panda::panda_joint1' type='revolute'>
        <pose relative_to='panda::panda_link0'>0 0 0.333 0 -0 0</pose>
        <parent>panda::panda_link0</parent>
        <child>panda::panda_link1</child>
        <axis>
          <xyz>0 0 1</xyz>
          <limit>
            <effort>87</effort>
            <lower>-2.89725</lower>
            <upper>2.89725</upper>
            <velocity>2.61799</velocity>
          </limit>
          <dynamics>
            <spring_reference>0</spring_reference>
            <spring_stiffness>0</spring_stiffness>
            <damping>21.75</damping>
            <friction>3.48</friction>
          </dynamics>
        </axis>
      </joint>
      <joint name='panda::panda_joint2' type='revolute'>
        <pose relative_to='panda::panda_link1'>0 0 0 -1.5708 0 0</pose>
        <parent>panda::panda_link1</parent>
        <child>panda::panda_link2</child>
        <axis>
          <xyz>0 0 1</xyz>
          <limit>
            <effort>87</effort>
            <lower>-1.76278</lower>
            <upper>1.76278</upper>
            <velocity>2.61799</velocity>
          </limit>
          <dynamics>
            <spring_reference>0</spring_reference>
            <spring_stiffness>0</spring_stiffness>
            <damping>21.75</damping>
            <friction>3.48</friction>
          </dynamics>
        </axis>
      </joint>
      <joint name='panda::panda_joint3' type='revolute'>
        <pose relative_to='panda::panda_link2'>0 -0.316 0 1.5708 -0 0</pose>
        <parent>panda::panda_link2</parent>
        <child>panda::panda_link3</child>
        <axis>
          <xyz>0 0 1</xyz>
          <limit>
            <effort>87</effort>
            <lower>-2.89725</lower>
            <upper>2.89725</upper>
            <velocity>2.61799</velocity>
          </limit>
          <dynamics>
            <spring_reference>0</spring_reference>
            <spring_stiffness>0</spring_stiffness>
            <damping>21.75</damping>
            <friction>3.48</friction>
          </dynamics>
        </axis>
      </joint>
      <joint name='panda::panda_joint4' type='revolute'>
        <pose relative_to='panda::panda_link3'>0.0825 0 0 1.5708 -0 0</pose>
        <parent>panda::panda_link3</parent>
        <child>panda::panda_link4</child>
        <axis>
          <xyz>0 0 1</xyz>
          <limit>
            <effort>87</effort>
            <lower>-3.07178</lower>
            <upper>-0.0698132</upper>
            <velocity>2.61799</velocity>
          </limit>
          <dynamics>
            <spring_reference>0</spring_reference>
            <spring_stiffness>0</spring_stiffness>
            <damping>21.75</damping>
            <friction>3.48</friction>
          </dynamics>
        </axis>
      </joint>
      <joint name='panda::panda_joint5' type='revolute'>
        <pose relative_to='panda::panda_link4'>-0.0825 0.384 0 -1.5708 0 0</pose>
        <parent>panda::panda_link4</parent>
        <child>panda::panda_link5</child>
        <axis>
          <xyz>0 0 1</xyz>
          <limit>
            <effort>12</effort>
            <lower>-2.89725</lower>
            <upper>2.89725</upper>
            <velocity>3.14159</velocity>
          </limit>
          <dynamics>
            <spring_reference>0</spring_reference>
            <spring_stiffness>0</spring_stiffness>
            <damping>3</damping>
            <friction>0.48</friction>
          </dynamics>
        </axis>
      </joint>
      <joint name='panda::panda_joint6' type='revolute'>
        <pose relative_to='panda::panda_link5'>0 0 0 1.5708 -0 0</pose>
        <parent>panda::panda_link5</parent>
        <child>panda::panda_link6</child>
        <axis>
          <xyz>0 0 1</xyz>
          <limit>
            <effort>12</effort>
            <lower>-0.0174533</lower>
            <upper>3.75246</upper>
            <velocity>3.14159</velocity>
          </limit>
          <dynamics>
            <spring_reference>0</spring_reference>
            <spring_stiffness>0</spring_stiffness>
            <damping>3</damping>
            <friction>0.48</friction>
          </dynamics>
        </axis>
      </joint>
      <joint name='panda::panda_joint7' type='revolute'>
        <pose relative_to='panda::panda_link6'>0.088 0 0 1.5708 -0 0</pose>
        <parent>panda::panda_link6</parent>
        <child>panda::panda_link7</child>
        <axis>
          <xyz>0 0 1</xyz>
          <limit>
            <effort>12</effort>
            <lower>-2.89725</lower>
            <upper>2.89725</upper>
            <velocity>3.14159</velocity>
          </limit>
          <dynamics>
            <spring_reference>0</spring_reference>
            <spring_stiffness>0</spring_stiffness>
            <damping>3</damping>
            <friction>0.48</friction>
          </dynamics>
        </axis>
      </joint>
      <joint name='panda::panda_hand_joint' type='fixed'>
        <pose relative_to='panda::panda_link7'>0 0 0.107 0 0 -0.785398</pose>
        <parent>panda::panda_link7</parent>
        <child>panda::panda_hand</child>
      </joint>
      <link name='panda::panda_hand'>
        <pose relative_to='panda::panda_hand_joint'>0 0 0 0 -0 0</pose>
        <visual name='panda_hand_visual'>
          <pose>0 0 0 0 -0 0</pose>
          <geometry>
            <mesh>
              <uri>meshes/visual/hand.dae</uri>
            </mesh>
          </geometry>
        </visual>
        <collision name='panda_hand_collision'>
          <pose>0 0 0 0 -0 0</pose>
          <geometry>
            <mesh>
              <uri>meshes/collision/hand.stl</uri>
            </mesh>
          </geometry>
          <surface>
            <friction>
              <ode>
                <mu>1.05</mu>
                <mu2>1.05</mu2>
              </ode>
              <torsional>
                <ode/>
              </torsional>
            </friction>
            <contact>
              <ode/>
            </contact>
            <bounce/>
          </surface>
          <max_contacts>10</max_contacts>
        </collision>
        <inertial>
          <pose>-7e-06 0.001524 0.027591 0 -0 0</pose>
          <mass>0.140608</mass>
          <inertia>
            <ixx>0.000536545</ixx>
            <iyy>7.70512e-05</iyy>
            <izz>0.000493818</izz>
            <ixy>1.7912e-08</ixy>
            <ixz>-2.32007e-08</ixz>
            <iyz>4.68115e-08</iyz>
          </inertia>
        </inertial>
        <self_collide>0</self_collide>
        <enable_wind>0</enable_wind>
        <kinematic>0</kinematic>
      </link>
      <link name='panda::panda_leftfinger'>
        <pose relative_to='panda::panda_finger_joint1'>0 0 0 0 -0 0</pose>
        <visual name='panda_leftfinger_visual'>
          <geometry>
            <mesh>
              <uri>meshes/visual/finger.dae</uri>
            </mesh>
          </geometry>
        </visual>
        <collision name='panda_leftfinger_collision'>
          <geometry>
            <mesh>
              <uri>meshes/collision/finger.stl</uri>
            </mesh>
          </geometry>
          <surface>
            <friction>
              <ode>
                <mu>2.15</mu>
                <mu2>2.15</mu2>
              </ode>
              <torsional>
                <ode/>
              </torsional>
            </friction>
            <contact>
              <ode/>
            </contact>
            <bounce/>
          </surface>
          <max_contacts>10</max_contacts>
        </collision>
        <inertial>
          <pose>-6e-06 0.002278 -0.027712 0 -0 0</pose>
          <mass>0.223845</mass>
          <inertia>
            <ixx>6.74804e-05</ixx>
            <iyy>6.62719e-05</iyy>
            <izz>1.5504e-05</izz>
            <ixy>-4.10274e-09</ixy>
            <ixz>1.86937e-08</ixz>
            <iyz>1.19675e-05</iyz>
          </inertia>
        </inertial>
        <self_collide>0</self_collide>
        <enable_wind>0</enable_wind>
        <kinematic>0</kinematic>
      </link>
      <link name='panda::panda_rightfinger'>
        <pose relative_to='panda::panda_finger_joint2'>0 0 0 0 -0 0</pose>
        <visual name='panda_rightfinger_visual'>
          <pose>0 0 0 0 -0 3.14159</pose>
          <geometry>
            <mesh>
              <uri>meshes/visual/finger.dae</uri>
            </mesh>
          </geometry>
        </visual>
        <collision name='panda_rightfinger_collision'>
          <pose>0 0 0 0 -0 3.14159</pose>
          <geometry>
            <mesh>
              <uri>meshes/collision/finger.stl</uri>
            </mesh>
          </geometry>
          <surface>
            <friction>
              <ode>
                <mu>2.15</mu>
                <mu2>2.15</mu2>
              </ode>
              <torsional>
                <ode/>
              </torsional>
            </friction>
            <contact>
              <ode/>
            </contact>
            <bounce/>
          </surface>
          <max_contacts>10</max_contacts>
        </collision>
        <inertial>
          <pose>-6e-06 0.002278 -0.027712 0 -0 3.14159</pose>
          <mass>0.223845</mass>
          <inertia>
            <ixx>6.74804e-05</ixx>
            <iyy>6.62719e-05</iyy>
            <izz>1.5504e-05</izz>
            <ixy>-4.10274e-09</ixy>
            <ixz>1.86937e-08</ixz>
            <iyz>1.19675e-05</iyz>
          </inertia>
        </inertial>
        <self_collide>0</self_collide>
        <enable_wind>0</enable_wind>
        <kinematic>0</kinematic>
      </link>
      <joint name='panda::panda_finger_joint1' type='prismatic'>
        <pose relative_to='panda::panda_hand'>0 0 0.0584 0 -0 0</pose>
        <parent>panda::panda_hand</parent>
        <child>panda::panda_leftfinger</child>
        <axis>
          <xyz>0 1 0</xyz>
          <limit>
            <effort>20</effort>
            <lower>0</lower>
            <upper>0.04</upper>
            <velocity>0.2</velocity>
          </limit>
          <dynamics>
            <spring_reference>0</spring_reference>
            <spring_stiffness>0</spring_stiffness>
            <damping>10</damping>
            <friction>0.5</friction>
          </dynamics>
        </axis>
      </joint>
      <joint name='panda::panda_finger_joint2' type='prismatic'>
        <pose relative_to='panda::panda_hand'>0 0 0.0584 0 -0 0</pose>
        <parent>panda::panda_hand</parent>
        <child>panda::panda_rightfinger</child>
        <axis>
          <xyz>0 -1 0</xyz>
          <limit>
            <effort>20</effort>
            <lower>0</lower>
            <upper>0.04</upper>
            <velocity>0.2</velocity>
          </limit>
          <dynamics>
            <spring_reference>0</spring_reference>
            <spring_stiffness>0</spring_stiffness>
            <damping>10</damping>
            <friction>0.5</friction>
          </dynamics>
        </axis>
      </joint>
      <link name='panda::panda_link8'>
        <pose relative_to='panda::end_effector_frame_fixed_joint'>0 0 0 0 -0 0</pose>
        <self_collide>0</self_collide>
        <inertial>
          <pose>0 0 0 0 -0 0</pose>
          <inertia>
            <ixx>1</ixx>
            <ixy>0</ixy>
            <ixz>0</ixz>
            <iyy>1</iyy>
            <iyz>0</iyz>
            <izz>1</izz>
          </inertia>
          <mass>1</mass>
        </inertial>
        <enable_wind>0</enable_wind>
        <kinematic>0</kinematic>
      </link>
      <joint name='panda::end_effector_frame_fixed_joint' type='fixed'>
        <pose relative_to='panda::panda_hand'>0 0 0.103 0 -0 0</pose>
        <parent>panda::panda_hand</parent>
        <child>panda::panda_link8</child>
      </joint>
      <plugin name='ignition::gazebo::systems::JointPositionController' filename='ignition-gazebo-joint-position-controller-system'>
        <joint_name>panda::panda_joint1</joint_name>
        <p_gain>50</p_gain>
        <d_gain>20</d_gain>
        <i_gain>0</i_gain>
        <i_min>-1</i_min>
        <i_max>1</i_max>
        <cmd_min>-87</cmd_min>
        <cmd_max>87</cmd_max>
      </plugin>
      <plugin name='ignition::gazebo::systems::JointPositionController' filename='ignition-gazebo-joint-position-controller-system'>
        <joint_name>panda::panda_joint2</joint_name>
        <p_gain>10000</p_gain>
        <d_gain>500</d_gain>
        <i_gain>0</i_gain>
        <i_min>-1</i_min>
        <i_max>1</i_max>
        <cmd_min>-87</cmd_min>
        <cmd_max>87</cmd_max>
      </plugin>
      <plugin name='ignition::gazebo::systems::JointPositionController' filename='ignition-gazebo-joint-position-controller-system'>
        <joint_name>panda::panda_joint3</joint_name>
        <p_gain>100</p_gain>
        <d_gain>10</d_gain>
        <i_gain>0</i_gain>
        <i_min>-1</i_min>
        <i_max>1</i_max>
        <cmd_min>-87</cmd_min>
        <cmd_max>87</cmd_max>
      </plugin>
      <plugin name='ignition::gazebo::systems::JointPositionController' filename='ignition-gazebo-joint-position-controller-system'>
        <joint_name>panda::panda_joint4</joint_name>
        <p_gain>1000</p_gain>
        <d_gain>50</d_gain>
        <i_gain>0</i_gain>
        <i_min>-1</i_min>
        <i_max>1</i_max>
        <cmd_min>-87</cmd_min>
        <cmd_max>87</cmd_max>
      </plugin>
      <plugin name='ignition::gazebo::systems::JointPositionController' filename='ignition-gazebo-joint-position-controller-system'>
        <joint_name>panda::panda_joint5</joint_name>
        <p_gain>100</p_gain>
        <d_gain>50</d_gain>
        <i_gain>0</i_gain>
        <i_min>-1</i_min>
        <i_max>1</i_max>
        <cmd_min>-12</cmd_min>
        <cmd_max>12</cmd_max>
      </plugin>
      <plugin name='ignition::gazebo::systems::JointPositionController' filename='ignition-gazebo-joint-position-controller-system'>
        <joint_name>panda::panda_joint6</joint_name>
        <p_gain>100</p_gain>
        <d_gain>10</d_gain>
        <i_gain>0</i_gain>
        <i_min>-1</i_min>
        <i_max>1</i_max>
        <cmd_min>-12</cmd_min>
        <cmd_max>12</cmd_max>
      </plugin>
      <plugin name='ignition::gazebo::systems::JointPositionController' filename='ignition-gazebo-joint-position-controller-system'>
        <joint_name>panda::panda_joint7</joint_name>
        <p_gain>10</p_gain>
        <d_gain>0.1</d_gain>
        <i_gain>0.5</i_gain>
        <i_min>-1</i_min>
        <i_max>1</i_max>
        <cmd_min>-12</cmd_min>
        <cmd_max>12</cmd_max>
      </plugin>
      <plugin name='ignition::gazebo::systems::JointPositionController' filename='ignition-gazebo-joint-position-controller-system'>
        <joint_name>panda::panda_finger_joint1</joint_name>
        <p_gain>100</p_gain>
        <d_gain>50</d_gain>
        <i_gain>0</i_gain>
        <i_min>-1</i_min>
        <i_max>1</i_max>
        <cmd_min>-20</cmd_min>
        <cmd_max>20</cmd_max>
      </plugin>
      <plugin name='ignition::gazebo::systems::JointPositionController' filename='ignition-gazebo-joint-position-controller-system'>
        <joint_name>panda::panda_finger_joint2</joint_name>
        <p_gain>100</p_gain>
        <d_gain>50</d_gain>
        <i_gain>0</i_gain>
        <i_min>-1</i_min>
        <i_max>1</i_max>
        <cmd_min>-20</cmd_min>
        <cmd_max>20</cmd_max>
      </plugin>
      <joint name='arm_to_chassis_joint' type='fixed'>
        <parent>chassis</parent>
        <child>panda::panda_link0</child>
      </joint>
      <plugin name='ignition::gazebo::systems::DiffDrive' filename='ignition-gazebo-diff-drive-system'>
        <left_joint>front_left_wheel_joint</left_joint>
        <left_joint>rear_left_wheel_joint</left_joint>
        <right_joint>front_right_wheel_joint</right_joint>
        <right_joint>rear_right_wheel_joint</right_joint>
        <wheel_separation>0.320</wheel_separation>
        <wheel_base>0.344</wheel_base>
        <wheel_radius>0.052988</wheel_radius>
        <topic>/model/rover/cmd_vel</topic>
        <odom_topic>/model/rover/odometry</odom_topic>
      </plugin>
      <pose>0.194377 -0.468746 0 0 -0 0</pose>
    </model>
    <model name='SCENE'>
      <static>1</static>
      <link name='link'>
        <visual name='visual'>
          <geometry>
            <mesh>
              <uri>model://SCENE/meshes/untitled.dae</uri>
              <scale>1 1 1</scale>
            </mesh>
          </geometry>
          <material>
            <script>
              <uri>model://SCENE/meshes</uri>
              <name>Material__64_003</name>
            </script>
          </material>
        </visual>
        <collision name='collision'>
          <geometry>
            <mesh>
              <uri>model://SCENE/meshes/untitled.dae</uri>
              <scale>1 1 1</scale>
            </mesh>
          </geometry>
          <max_contacts>10</max_contacts>
          <surface>
            <contact>
              <ode/>
            </contact>
            <bounce/>
            <friction>
              <torsional>
                <ode/>
              </torsional>
              <ode/>
            </friction>
          </surface>
        </collision>
        <self_collide>0</self_collide>
        <enable_wind>0</enable_wind>
        <kinematic>0</kinematic>
      </link>
      <pose>1.80876 0.326168 0 0 -0 0</pose>
    </model>
    <state world_name='default'>
      <sim_time>77 77000000</sim_time>
      <real_time>218 202246636</real_time>
      <wall_time>1750498924 963968355</wall_time>
      <iterations>77077</iterations>
      <model name='SCENE'>
        <pose>1.80876 0.326168 0 0 -0 0</pose>
        <scale>1 1 1</scale>
        <link name='link'>
          <pose>1.80876 0.326168 0 0 -0 0</pose>
          <velocity>0 0 0 0 -0 0</velocity>
          <acceleration>0 0 0 0 -0 0</acceleration>
          <wrench>0 0 0 0 -0 0</wrench>
        </link>
      </model>
      <model name='ground_plane'>
        <pose>0 0 0 0 -0 0</pose>
        <scale>1 1 1</scale>
        <link name='link'>
          <pose>0 0 0 0 -0 0</pose>
          <velocity>0 0 0 0 -0 0</velocity>
          <acceleration>0 0 0 0 -0 0</acceleration>
          <wrench>0 0 0 0 -0 0</wrench>
        </link>
      </model>
      <model name='rover'>
        <pose>1.52091 0.323349 0.145828 -1e-06 -3e-05 0.577445</pose>
        <scale>1 1 1</scale>
        <link name='chassis'>
          <pose>1.52091 0.323349 0.145828 -1e-06 -3e-05 0.577445</pose>
          <velocity>0.034475 0.024556 -0.004396 0.020447 -0.030294 -0.00307</velocity>
          <acceleration>0.171007 -0.044273 -8.68506 -1.81275 -1.42899 0.114215</acceleration>
          <wrench>17.1007 -4.42734 -868.506 0 -0 0</wrench>
        </link>
        <link name='front_left_wheel'>
          <pose>1.5774 0.552137 0.052984 -3.7e-05 -0.123585 0.577456</pose>
          <velocity>0.037918 0.0265 0.002024 0.05054 -0.073078 -0.005232</velocity>
          <acceleration>1.01736 1.61161 -4.41511 -0.555942 1.1968 -0.63394</acceleration>
          <wrench>5.08679 8.05806 -22.0755 0 -0 0</wrench>
        </link>
        <link name='front_right_wheel'>
          <pose>1.753 0.282619 0.052984 3.14154 0.10537 -2.56414</pose>
          <velocity>0.036956 0.025889 0.002662 0.0365 0.052241 -0.00139</velocity>
          <acceleration>0.931347 1.36934 -3.3583 2.96511 0.824977 0.83677</acceleration>
          <wrench>4.65674 6.84669 -16.7915 0 -0 0</wrench>
        </link>
        <link name='panda::panda_hand'>
          <pose>1.58804 0.1292 -0.132164 -2.51229 -0.549099 0.295929</pose>
          <velocity>0.032629 0.02553 0.001372 0.008134 0.001456 0.029263</velocity>
          <acceleration>0.504311 -0.235605 -0.283807 2.47114 0.725453 1.30551</acceleration>
          <wrench>0.07091 -0.033128 -0.039905 0 -0 0</wrench>
        </link>
        <link name='panda::panda_leftfinger'>
          <pose>1.62277 0.141913 -0.192527 -2.51236 -0.548864 0.296003</pose>
          <velocity>0.032385 0.026662 0.002417 0.016843 -0.020476 0.002454</velocity>
          <acceleration>0.0122 -0.457362 0.564701 1.21298 -1.40139 0.518535</acceleration>
          <wrench>0.002731 -0.102378 0.126405 0 -0 0</wrench>
        </link>
        <link name='panda::panda_link0'>
          <pose>1.52092 0.323333 0.195829 -5.2e-05 -1.9e-05 0.577444</pose>
          <velocity>0.033542 0.025404 -0.003979 0.023174 -0.032528 -0.002895</velocity>
          <acceleration>-3.4803 0.187865 -9.42128 -0.442755 0.28661 -2.63962</acceleration>
          <wrench>-9.79449 0.528701 -26.514 0 -0 0</wrench>
        </link>
        <link name='panda::panda_link1'>
          <pose>1.5209 0.323356 0.528827 2.8e-05 6.6e-05 -1.049</pose>
          <velocity>0.024221 0.019541 -0.004011 0.009725 -0.027716 0.030324</velocity>
          <acceleration>-6.45198 -4.51653 -9.2669 1.69573 0.744827 1.57039</acceleration>
          <wrench>-17.0547 -11.9386 -24.4954 0 -0 0</wrench>
        </link>
        <link name='panda::panda_link2'>
          <pose>1.5209 0.323358 0.528815 1.57021 1.37868 2.09201</pose>
          <velocity>0.024195 0.019769 -0.004159 0.006293 -0.02698 0.031471</velocity>
          <acceleration>-8.06778 -2.99989 -6.232 -2.61197 0.582301 2.20705</acceleration>
          <wrench>-21.5029 -7.99554 -16.61 0 -0 0</wrench>
        </link>
        <link name='panda::panda_link3'>
          <pose>1.67551 0.054452 0.46846 -2.82943 1.36869 2.41083</pose>
          <velocity>0.033769 0.025147 8.8e-05 -0.003135 -0.016117 0.028739</velocity>
          <acceleration>-3.74994 -1.90552 -0.934196 2.98017 -0.126059 0.053373</acceleration>
          <wrench>-8.73501 -4.43865 -2.17609 0 -0 0</wrench>
        </link>
        <link name='panda::panda_link4'>
          <pose>1.66318 0.065504 0.387637 -1.50555 -0.33289 2.08324</pose>
          <velocity>0.034364 0.025101 -0.000152 -3.2e-05 -0.005765 0.037175</velocity>
          <acceleration>-1.52783 -2.33641 -0.968322 -1.03765 0.970601 -1.43164</acceleration>
          <wrench>-3.53001 -5.39823 -2.23729 0 -0 0</wrench>
        </link>
        <link name='panda::panda_link5'>
          <pose>1.61819 0.094405 -0.001472 -2.80818 -0.062306 0.887766</pose>
          <velocity>0.034362 0.025873 0.000543 0.007824 -0.003142 0.028544</velocity>
          <acceleration>0.384755 -0.335244 0.646722 -2.46386 1.30217 -0.755084</acceleration>
          <wrench>1.00907 -0.879225 1.69612 0 -0 0</wrench>
        </link>
        <link name='panda::panda_link6'>
          <pose>1.61819 0.094404 -0.001473 1.12848 0.702691 -2.52929</pose>
          <velocity>0.03417 0.025818 0.000826 0.007164 -0.002921 0.028507</velocity>
          <acceleration>2.11767 0.166166 -0.21593 0.743332 -1.55577 2.97698</acceleration>
          <wrench>3.18197 0.249678 -0.324452 0 -0 0</wrench>
        </link>
        <link name='panda::panda_link7'>
          <pose>1.56324 0.055804 -0.058351 -2.3319 -0.014078 -0.312665</pose>
          <velocity>0.035093 0.024797 0.000524 0.00723 -0.002067 0.029354</velocity>
          <acceleration>2.59755 0.473866 0.005449 1.47245 -0.316463 -0.039258</acceleration>
          <wrench>1.36051 0.248195 0.002854 0 -0 0</wrench>
        </link>
        <link name='panda::panda_link8'>
          <pose>1.61192 0.199859 -0.203203 -2.51236 -0.548935 0.296048</pose>
          <velocity>0.031008 0.026148 0.001826 0.001444 0.003192 0.011608</velocity>
          <acceleration>0.10518 -0.33571 0.038339 -0.110268 0.042522 0.102667</acceleration>
          <wrench>0.10518 -0.33571 0.038339 0 -0 0</wrench>
        </link>
        <link name='panda::panda_rightfinger'>
          <pose>1.60159 0.169263 -0.172444 -2.51241 -0.548923 0.296072</pose>
          <velocity>0.0319 0.026304 0.0025 0.019656 -0.018545 0.005653</velocity>
          <acceleration>-0.025532 -0.370564 0.259795 2.37546 0.420111 1.33874</acceleration>
          <wrench>-0.005715 -0.082949 0.058154 0 -0 0</wrench>
        </link>
        <link name='rear_left_wheel'>
          <pose>1.28878 0.364091 0.052975 -2.5e-05 -0.124298 0.577449</pose>
          <velocity>0.037395 0.027279 -0.010634 -0.056441 0.101027 -0.003293</velocity>
          <acceleration>1.88332 0.994434 -12.914 -2.82613 1.0368 0.200466</acceleration>
          <wrench>9.41662 4.97217 -64.57 0 -0 0</wrench>
        </link>
        <link name='rear_right_wheel'>
          <pose>1.46438 0.094566 0.052975 -3.14159 0.119515 -2.56415</pose>
          <velocity>0.036491 0.026624 -0.010992 -0.049653 0.081361 -0.002715</velocity>
          <acceleration>1.81415 0.755412 -13.1928 2.59698 -1.13933 -0.650331</acceleration>
          <wrench>9.07073 3.77706 -65.964 0 -0 0</wrench>
        </link>
      </model>
      <light name='sun'>
        <pose>0 0 10 0 -0 0</pose>
      </light>
    </state>
    <gui fullscreen='0'>
      <camera name='user_camera'>
        <pose>13.16 52.0892 25.4893 -0 0.487643 -1.843</pose>
        <view_controller>orbit</view_controller>
        <projection_type>perspective</projection_type>
      </camera>
    </gui>
  </world>
</sdf>
