<?xml version="1.0"?>
<robot name="Bazu">

    <link name="world"/>

    <link name="base_link">
        <visual >
            <origin xyz="0.0 0.0 0.0" rpy="0.0 0.0 0.0"/>
            <geometry>
                <box size="0.0 0.0 0.0"/>
            </geometry>
            <material name="">
                <color rgba="1.0 0.0 0.0 1.0"/>
                <texture filename=""/>
            </material>
        </visual>
        <collision>
            <origin xyz="0.0 0.0 0.0" rpy="0.0 0.0 0.0"/>
            <geometry>
                <box size="0.0 0.0 0.0"/>
            </geometry>
        </collision>
    </link>
    <joint name="fixed" type="fixed">
        <parent link="world"/>
        <child link="base_link"/>
        <origin xyz="0.0 0.0 0.0" rpy="0.0 0.0 0.0"/>
    </joint>

    <link name="link_1">
        <visual >
            <origin xyz="0.0 0.0 0.0" rpy="0.0 0.0 0.0"/>
            <geometry>
                <box size="0.0 0.0 0.0"/>
            </geometry>
            <material name="">
                <color rgba="1.0 0.0 0.0 1.0"/>
                <texture filename=""/>
            </material>
        </visual>
        <collision>
            <origin xyz="0.0 0.0 0.0" rpy="0.0 0.0 0.0"/>
            <geometry>
                <box size="0.0 0.0 0.0"/>
            </geometry>
        </collision>
    </link>
    <link name="link_2">
        <visual >
            <origin xyz="0.0 0.0 0.0" rpy="0.0 0.0 0.0"/>
            <geometry>
                <box size="0.0 0.0 0.0"/>
            </geometry>
            <material name="">
                <color rgba="1.0 0.0 0.0 1.0"/>
                <texture filename=""/>
            </material>
        </visual>
        <collision>
            <origin xyz="0.0 0.0 0.0" rpy="0.0 0.0 0.0"/>
            <geometry>
                <box size="0.0 0.0 0.0"/>
            </geometry>
        </collision>
    </link>
    <link name="link_3">
        <visual >
            <origin xyz="0.0 0.0 0.0" rpy="0.0 0.0 0.0"/>
            <geometry>
                <box size="0.0 0.0 0.0"/>
            </geometry>
            <material name="">
                <color rgba="1.0 0.0 0.0 1.0"/>
                <texture filename=""/>
            </material>
        </visual>
        <collision>
            <origin xyz="0.0 0.0 0.0" rpy="0.0 0.0 0.0"/>
            <geometry>
                <box size="0.0 0.0 0.0"/>
            </geometry>
        </collision>
    </link>
    <joint name="joint_1" type="continuous">
        <axis xyz="0 0 1"/>
        <parent link="base_link"/>
        <child link="link_1"/>
        <origin xyz="0.0 0.0 0.0" rpy="0.0 0.0 0.0"/>
    </joint>
    <joint name="joint_2" type="fixed">
        <parent link="link_1"/>
        <child link="link_2"/>
        <origin xyz="0.0 0.0 0.0" rpy="0.0 0.0 0.0"/>
    </joint>
    <joint name="joint_3" type="fixed">
        <parent link="link_2"/>
        <child link="link_3"/>
        <origin xyz="0.0 0.0 0.0" rpy="0.0 0.0 0.0"/>
    </joint>

    <!-- adding ros2 controller -->

    <ros2_control name="GazeboSystem" type="system">
        <hardware>
          <plugin>gazebo_ros2_control/GazeboSystem</plugin>
        </hardware>
        <joint name="slider_to_cart">
          <command_interface name="effort">
            <param name="min">-1000</param>
            <param name="max">1000</param>
          </command_interface>
          <state_interface name="position">
            <param name="initial_value">1.0</param>
          </state_interface>
          <state_interface name="velocity"/>
          <state_interface name="effort"/>
        </joint>
      </ros2_control>

      <gazebo>
        <plugin filename="libgazebo_ros2_control.so" name="gazebo_ros2_control">
          <parameters>$(find gazebo_ros2_control_demos)/config/cart_controller.yaml</parameters>
        </plugin>
      </gazebo>
</robot>
