<?xml version="1.0" ?>
<!-- =================================================================================== -->
<!-- |    This document was autogenerated by xacro from panda.urdf.xacro               | -->
<!-- |    EDITING THIS FILE BY HAND IS NOT RECOMMENDED                                 | -->
<!-- =================================================================================== -->
<robot name="panda_2" xmlns:xacro="http://www.ros.org/wiki/xacro">

<!-- <xacro:include filename="$(find franka_description)/urdf/mobile_base.xacro"/> -->

<!--  -->
<gazebo reference="rear_left_wheel">
  <material>Gazebo/Black</material>
  <mu1>0.40</mu1>
  <mu2>0.40</mu2>
</gazebo>
<gazebo reference="rear_right_wheel">
  <material>Gazebo/Black</material>
  <mu1>0.40</mu1>
  <mu2>0.40</mu2>
</gazebo>
<gazebo reference="front_right_wheel">
  <material>Gazebo/Black</material>
  <mu1>1.0</mu1>
  <mu2>1.0</mu2>
</gazebo>
<gazebo reference="front_left_wheel">
  <material>Gazebo/Black</material>
  <mu1>1.0</mu1>
  <mu2>1.0</mu2>
</gazebo>
<gazebo reference="mobile_base_link">
  <material>Gazebo/Blue</material>
  <mu1>0.8</mu1>
  <mu2>0.8</mu2>
</gazebo>
<gazebo reference="chassis_top">
  <material>Gazebo/DarkGrey</material>
</gazebo>
<gazebo reference="front_bumper">
  <material>Gazebo/Orange</material>
</gazebo>
<gazebo reference="rear_bumper">
  <material>Gazebo/Orange</material>
</gazebo>

<!-- Mobile base -->
<link name="base_link">
</link>

<joint name="base_to_mobile_base_joint" type="fixed">
  <origin xyz="0.0 0.0 0.10" rpy="0.0 0.0 0.0"/>
  <parent link="base_link"/>
  <child link="mobile_base_link"/>
</joint>

<!-- Enhanced Base Link - Main chassis with rounded corners -->
<link name="mobile_base_link">
  <!-- Main chassis body -->
  <visual>
    <origin xyz="0 0 0.05" rpy="0 0 0"/>
    <geometry>
      <box size="0.6 0.4 0.1"/>
    </geometry>
    <material name="chassis_material">
      <color rgba="0.2 0.4 0.8 1.0"/>
    </material>
  </visual>
  
  <!-- Chassis top plate with different color -->
  <visual name="top_plate">
    <origin xyz="0 0 0.105" rpy="0 0 0"/>
    <geometry>
      <box size="0.58 0.38 0.01"/>
    </geometry>
    <material name="top_plate_material">
      <color rgba="0.15 0.15 0.15 1.0"/>
    </material>
  </visual>
  
  <!-- Side accent strips -->
  <visual name="left_accent">
    <origin xyz="0 0.205 0.05" rpy="0 0 0"/>
    <geometry>
      <box size="0.5 0.01 0.08"/>
    </geometry>
    <material name="accent_material">
      <color rgba="0.9 0.4 0.1 1.0"/>
    </material>
  </visual>
  
  <visual name="right_accent">
    <origin xyz="0 -0.205 0.05" rpy="0 0 0"/>
    <geometry>
      <box size="0.5 0.01 0.08"/>
    </geometry>
    <material name="accent_material">
      <color rgba="0.9 0.4 0.1 1.0"/>
    </material>
  </visual>
  
  <!-- Front grille elements -->
  <visual name="front_grille_1">
    <origin xyz="0.295 0.1 0.05" rpy="0 0 0"/>
    <geometry>
      <box size="0.01 0.15 0.06"/>
    </geometry>
    <material name="grille_material">
      <color rgba="0.1 0.1 0.1 1.0"/>
    </material>
  </visual>
  
  <visual name="front_grille_2">
    <origin xyz="0.295 -0.1 0.05" rpy="0 0 0"/>
    <geometry>
      <box size="0.01 0.15 0.06"/>
    </geometry>
    <material name="grille_material">
      <color rgba="0.1 0.1 0.1 1.0"/>
    </material>
  </visual>
  
  <!-- Rear vents -->
  <visual name="rear_vent_1">
    <origin xyz="-0.295 0.05 0.05" rpy="0 0 0"/>
    <geometry>
      <box size="0.01 0.08 0.04"/>
    </geometry>
    <material name="vent_material">
      <color rgba="0.05 0.05 0.05 1.0"/>
    </material>
  </visual>
  
  <visual name="rear_vent_2">
    <origin xyz="-0.295 -0.05 0.05" rpy="0 0 0"/>
    <geometry>
      <box size="0.01 0.08 0.04"/>
    </geometry>
    <material name="vent_material">
      <color rgba="0.05 0.05 0.05 1.0"/>
    </material>
  </visual>
  
  <collision>
    <origin xyz="0 0 0.05" rpy="0 0 0"/>
    <geometry>
      <box size="0.6 0.4 0.1"/>
    </geometry>
  </collision>
  
  <inertial>
    <origin xyz="0 0 0.05" rpy="0 0 0"/>
    <mass value="150.0"/>
    <inertia ixx="0.35" ixy="0.0" ixz="0.0"
             iyy="0.85" iyz="0.0"
             izz="1.0"/>
  </inertial>
</link>

<!-- Front Bumper -->
<!-- <joint name="front_bumper_joint" type="fixed">
  <parent link="mobile_base_link"/>
  <child link="front_bumper"/>
  <origin xyz="0.32 0.0 0.03" rpy="0 0 0"/>
</joint>

<link name="front_bumper">
  <visual>
    <origin xyz="0 0 0" rpy="0 0 0"/>
    <geometry>
      <cylinder radius="0.02" length="0.35"/>
    </geometry>
    <material name="bumper_material">
      <color rgba="0.9 0.4 0.1 1.0"/>
    </material>
  </visual>
  <collision>
    <origin xyz="0 0 0" rpy="0 0 0"/>
    <geometry>
      <cylinder radius="0.02" length="0.35"/>
    </geometry>
  </collision>
  <inertial>
    <origin xyz="0 0 0" rpy="0 0 0"/>
    <mass value="0.5"/>
    <inertia ixx="0.001" ixy="0.0" ixz="0.0"
             iyy="0.001" iyz="0.0"
             izz="0.001"/>
  </inertial>
</link> -->

<!-- Rear Bumper -->
<!-- <joint name="rear_bumper_joint" type="fixed">
  <parent link="mobile_base_link"/>
  <child link="rear_bumper"/>
  <origin xyz="-0.32 0.0 0.03" rpy="0 0 0"/>
</joint>

<link name="rear_bumper">
  <visual>
    <origin xyz="0 0 0" rpy="0 0 0"/>
    <geometry>
      <cylinder radius="0.02" length="0.35"/>
    </geometry>
    <material name="bumper_material">
      <color rgba="0.9 0.4 0.1 1.0"/>
    </material>
  </visual>
  <collision>
    <origin xyz="0 0 0" rpy="0 0 0"/>
    <geometry>
      <cylinder radius="0.02" length="0.35"/>
    </geometry>
  </collision>
  <inertial>
    <origin xyz="0 0 0" rpy="0 0 0"/>
    <mass value="0.5"/>
    <inertia ixx="0.001" ixy="0.0" ixz="0.0"
             iyy="0.001" iyz="0.0"
             izz="0.001"/>
  </inertial>
</link> -->

<!-- Enhanced Front Left Wheel with tire tread -->
<joint name="front_left_wheel_joint" type="continuous">
  <parent link="mobile_base_link"/>
  <child link="front_left_wheel"/>
  <origin xyz="0.2 0.25 0.0" rpy="-1.5708 0 0"/>
  <axis xyz="0 0 1"/>
</joint>

<link name="front_left_wheel">
  <!-- Main wheel -->
  <visual>
    <geometry>
      <cylinder radius="0.1" length="0.05"/>
    </geometry>
    <material name="wheel_material">
      <color rgba="0.1 0.1 0.1 1.0"/>
    </material>
  </visual>
  
  <!-- Wheel rim -->
  <visual name="rim">
    <origin xyz="0 0 0.02" rpy="0 0 0"/>
    <geometry>
      <cylinder radius="0.08" length="0.01"/>
    </geometry>
    <material name="rim_material">
      <color rgba="0.7 0.7 0.7 1.0"/>
    </material>
  </visual>
  
  <!-- Hub cap -->
  <visual name="hub">
    <origin xyz="0 0 0.025" rpy="0 0 0"/>
    <geometry>
      <cylinder radius="0.03" length="0.005"/>
    </geometry>
    <material name="hub_material">
      <color rgba="0.9 0.9 0.9 1.0"/>
    </material>
  </visual>
  
  <collision>
    <geometry>
      <cylinder radius="0.1" length="0.05"/>
    </geometry>
  </collision>
  
  <inertial>
    <mass value="1.0"/>
    <inertia ixx="0.0052" ixy="0.0" ixz="0.0"
             iyy="0.0052" iyz="0.0"
             izz="0.005"/>
  </inertial>
</link>

<!-- Enhanced Front Right Wheel -->
<joint name="front_right_wheel_joint" type="continuous">
  <parent link="mobile_base_link"/>
  <child link="front_right_wheel"/>
  <origin xyz="0.2 -0.25 0.0" rpy="-1.5708 0 0"/>
  <axis xyz="0 0 1"/>
</joint>

<link name="front_right_wheel">
  <!-- Main wheel -->
  <visual>
    <geometry>
      <cylinder radius="0.1" length="0.05"/>
    </geometry>
    <material name="wheel_material">
      <color rgba="0.1 0.1 0.1 1.0"/>
    </material>
  </visual>
  
  <!-- Wheel rim -->
  <visual name="rim">
    <origin xyz="0 0 -0.02" rpy="0 0 0"/>
    <geometry>
      <cylinder radius="0.08" length="0.01"/>
    </geometry>
    <material name="rim_material">
      <color rgba="0.7 0.7 0.7 1.0"/>
    </material>
  </visual>
  
  <!-- Hub cap -->
  <visual name="hub">
    <origin xyz="0 0 -0.025" rpy="0 0 0"/>
    <geometry>
      <cylinder radius="0.03" length="0.005"/>
    </geometry>
    <material name="hub_material">
      <color rgba="0.9 0.9 0.9 1.0"/>
    </material>
  </visual>
  
  <collision>
    <geometry>
      <cylinder radius="0.1" length="0.05"/>
    </geometry>
  </collision>
  
  <inertial>
    <mass value="1.0"/>
    <inertia ixx="0.0052" ixy="0.0" ixz="0.0"
             iyy="0.0052" iyz="0.0"
             izz="0.005"/>
  </inertial>
</link>

<!-- Enhanced Rear Left Wheel -->
<joint name="rear_left_wheel_joint" type="continuous">
  <parent link="mobile_base_link"/>
  <child link="rear_left_wheel"/>
  <origin xyz="-0.2 0.25 0.0" rpy="-1.5708 0 0"/>
  <axis xyz="0 0 1"/>
</joint>

<link name="rear_left_wheel">
  <!-- Main wheel -->
  <visual>
    <geometry>
      <cylinder radius="0.1" length="0.05"/>
    </geometry>
    <material name="wheel_material">
      <color rgba="0.1 0.1 0.1 1.0"/>
    </material>
  </visual>
  
  <!-- Wheel rim -->
  <visual name="rim">
    <origin xyz="0 0 0.02" rpy="0 0 0"/>
    <geometry>
      <cylinder radius="0.08" length="0.01"/>
    </geometry>
    <material name="rim_material">
      <color rgba="0.7 0.7 0.7 1.0"/>
    </material>
  </visual>
  
  <!-- Hub cap -->
  <visual name="hub">
    <origin xyz="0 0 0.025" rpy="0 0 0"/>
    <geometry>
      <cylinder radius="0.03" length="0.005"/>
    </geometry>
    <material name="hub_material">
      <color rgba="0.9 0.9 0.9 1.0"/>
    </material>
  </visual>
  
  <collision>
    <geometry>
      <cylinder radius="0.1" length="0.05"/>
    </geometry>
  </collision>
  
  <inertial>
    <mass value="1.0"/>
    <inertia ixx="0.0052" ixy="0.0" ixz="0.0"
             iyy="0.0052" iyz="0.0"
             izz="0.005"/>
  </inertial>
</link>

<!-- Enhanced Rear Right Wheel -->
<joint name="rear_right_wheel_joint" type="continuous">
  <parent link="mobile_base_link"/>
  <child link="rear_right_wheel"/>
  <origin xyz="-0.2 -0.25 0.0" rpy="-1.5708 0 0"/>
  <axis xyz="0 0 1"/>
</joint>

<link name="rear_right_wheel">
  <!-- Main wheel -->
  <visual>
    <geometry>
      <cylinder radius="0.1" length="0.05"/>
    </geometry>
    <material name="wheel_material">
      <color rgba="0.1 0.1 0.1 1.0"/>
    </material>
  </visual>
  
  <!-- Wheel rim -->
  <visual name="rim">
    <origin xyz="0 0 -0.02" rpy="0 0 0"/>
    <geometry>
      <cylinder radius="0.08" length="0.01"/>
    </geometry>
    <material name="rim_material">
      <color rgba="0.7 0.7 0.7 1.0"/>
    </material>
  </visual>
  
  <!-- Hub cap -->
  <visual name="hub">
    <origin xyz="0 0 -0.025" rpy="0 0 0"/>
    <geometry>
      <cylinder radius="0.03" length="0.005"/>
    </geometry>
    <material name="hub_material">
      <color rgba="0.9 0.9 0.9 1.0"/>
    </material>
  </visual>
  
  <collision>
    <geometry>
      <cylinder radius="0.1" length="0.05"/>
    </geometry>
  </collision>
  
  <inertial>
    <mass value="1.0"/>
    <inertia ixx="0.0052" ixy="0.0" ixz="0.0"
             iyy="0.0052" iyz="0.0"
             izz="0.005"/>
  </inertial>
</link>

<!-- Chassis Top Plate -->
<joint name="chassis_top_joint" type="fixed">
  <parent link="mobile_base_link"/>
  <child link="chassis_top"/>
  <origin xyz="0.0 0.0 0.11" rpy="0 0 0"/>
</joint>

<link name="chassis_top">
  <!-- Main top plate -->
  <visual>
    <origin xyz="0 0 0.005" rpy="0 0 0"/>
    <geometry>
      <box size="0.55 0.35 0.01"/>
    </geometry>
    <material name="top_material">
      <color rgba="0.3 0.3 0.3 1.0"/>
    </material>
  </visual>
  
  <!-- Decorative corner brackets -->
  <visual name="corner_fl">
    <origin xyz="0.25 0.15 0.01" rpy="0 0 0"/>
    <geometry>
      <box size="0.05 0.05 0.005"/>
    </geometry>
    <material name="bracket_material">
      <color rgba="0.6 0.6 0.6 1.0"/>
    </material>
  </visual>
  
  <visual name="corner_fr">
    <origin xyz="0.25 -0.15 0.01" rpy="0 0 0"/>
    <geometry>
      <box size="0.05 0.05 0.005"/>
    </geometry>
    <material name="bracket_material">
      <color rgba="0.6 0.6 0.6 1.0"/>
    </material>
  </visual>
  
  <visual name="corner_rl">
    <origin xyz="-0.25 0.15 0.01" rpy="0 0 0"/>
    <geometry>
      <box size="0.05 0.05 0.005"/>
    </geometry>
    <material name="bracket_material">
      <color rgba="0.6 0.6 0.6 1.0"/>
    </material>
  </visual>
  
  <visual name="corner_rr">
    <origin xyz="-0.25 -0.15 0.01" rpy="0 0 0"/>
    <geometry>
      <box size="0.05 0.05 0.005"/>
    </geometry>
    <material name="bracket_material">
      <color rgba="0.6 0.6 0.6 1.0"/>
    </material>
  </visual>
  
  <collision>
    <origin xyz="0 0 0.005" rpy="0 0 0"/>
    <geometry>
      <box size="0.55 0.35 0.01"/>
    </geometry>
  </collision>
  
  <inertial>
    <origin xyz="0 0 0.005" rpy="0 0 0"/>
    <mass value="2.0"/>
    <inertia ixx="0.02" ixy="0.0" ixz="0.0"
             iyy="0.05" iyz="0.0"
             izz="0.06"/>
  </inertial>
</link>

<!-- Enhanced Panda Arm Mounting Point -->
<joint name="base_mount_joint" type="fixed">
  <parent link="mobile_base_link"/>
  <child link="panda_mount_link"/>
  <origin xyz="0.0 0.0 0.1" rpy="0 0 0"/>
</joint>

<joint name="panda_mount_joint" type="fixed">
  <parent link="panda_mount_link"/>
  <child link="panda_link0"/>
  <origin xyz="0.0 0.0 0.05" rpy="0 0 0"/>
</joint>

<link name="panda_mount_link">
  <!-- Main mounting cylinder -->
  <visual>
    <origin xyz="0 0 0.025" rpy="0 0 0"/>
    <geometry>
      <cylinder radius="0.15" length="0.05"/>
    </geometry>
    <material name="mount_material">
      <color rgba="0.4 0.4 0.4 1.0"/>
    </material>
  </visual>
  
  <!-- Mounting flange -->
  <visual name="flange">
    <origin xyz="0 0 0.055" rpy="0 0 0"/>
    <geometry>
      <cylinder radius="0.18" length="0.01"/>
    </geometry>
    <material name="flange_material">
      <color rgba="0.5 0.5 0.5 1.0"/>
    </material>
  </visual>
  
  <!-- Decorative bolt holes -->
  <visual name="bolt_1">
    <origin xyz="0.14 0 0.06" rpy="0 0 0"/>
    <geometry>
      <cylinder radius="0.01" length="0.005"/>
    </geometry>
    <material name="bolt_material">
      <color rgba="0.2 0.2 0.2 1.0"/>
    </material>
  </visual>
  
  <visual name="bolt_2">
    <origin xyz="-0.14 0 0.06" rpy="0 0 0"/>
    <geometry>
      <cylinder radius="0.01" length="0.005"/>
    </geometry>
    <material name="bolt_material">
      <color rgba="0.2 0.2 0.2 1.0"/>
    </material>
  </visual>
  
  <visual name="bolt_3">
    <origin xyz="0 0.14 0.06" rpy="0 0 0"/>
    <geometry>
      <cylinder radius="0.01" length="0.005"/>
    </geometry>
    <material name="bolt_material">
      <color rgba="0.2 0.2 0.2 1.0"/>
    </material>
  </visual>
  
  <visual name="bolt_4">
    <origin xyz="0 -0.14 0.06" rpy="0 0 0"/>
    <geometry>
      <cylinder radius="0.01" length="0.005"/>
    </geometry>
    <material name="bolt_material">
      <color rgba="0.2 0.2 0.2 1.0"/>
    </material>
  </visual>
  
  <collision>
    <origin xyz="0 0 0.025" rpy="0 0 0"/>
    <geometry>
      <cylinder radius="0.08" length="0.05"/>
    </geometry>
  </collision>
  
  <inertial>
    <origin xyz="0 0 0.025" rpy="0 0 0"/>
    <mass value="0.5"/>
    <inertia ixx="0.001" ixy="0.0" ixz="0.0"
             iyy="0.001" iyz="0.0"
             izz="0.0016"/>
  </inertial>
</link>

<!-- LED Status Indicators -->
<joint name="led_strip_joint" type="fixed">
  <parent link="mobile_base_link"/>
  <child link="led_strip"/>
  <origin xyz="0.0 0.0 0.11" rpy="0 0 0"/>
</joint>

<link name="led_strip">
  <!-- Front LED strip -->
  <visual name="front_led">
    <origin xyz="0.28 0 0.02" rpy="0 0 0"/>
    <geometry>
      <box size="0.02 0.25 0.01"/>
    </geometry>
    <material name="led_material">
      <color rgba="0.1 0.8 0.1 1.0"/>
    </material>
  </visual>
  
  <!-- Rear LED strip -->
  <visual name="rear_led">
    <origin xyz="-0.28 0 0.02" rpy="0 0 0"/>
    <geometry>
      <box size="0.02 0.25 0.01"/>
    </geometry>
    <material name="led_material">
      <color rgba="0.8 0.1 0.1 1.0"/>
    </material>
  </visual>
  
  <inertial>
    <origin xyz="0 0 0" rpy="0 0 0"/>
    <mass value="0.1"/>
    <inertia ixx="0.0001" ixy="0.0" ixz="0.0"
             iyy="0.0001" iyz="0.0"
             izz="0.0001"/>
  </inertial>
</link>
<!--  -->

  <!-- sub-link defining detailed meshes for collision with environment -->
  <link name="panda_link0">
    <visual>
      <geometry>
        <mesh filename="file://$(find franka_description)/meshes/visual/link0.dae"/>
      </geometry>
    </visual>
    <collision>
      <geometry>
        <mesh filename="file://$(find franka_description)/meshes/collision/link0.stl"/>
      </geometry>
    </collision>
    <inertial>
      <origin rpy="0 0 0" xyz="-0.041018 -0.00014 0.049974"/>
      <mass value="0.629769"/>
      <inertia ixx="0.00315" ixy="8.2904e-07" ixz="0.00015" iyy="0.00388" iyz="8.2299e-06" izz="0.004285"/>
    </inertial>
  </link>
  <!-- sub-link defining coarse geometries of real robot's internal self-collision -->
  <link name="panda_link0_sc">
  </link>
  <!-- fixed joint between both sub-links -->
  <joint name="panda_link0_sc_joint" type="fixed">
    <origin rpy="0 0 0"/>
    <parent link="panda_link0"/>
    <child link="panda_link0_sc"/>
  </joint>
  <!-- sub-link defining detailed meshes for collision with environment -->
  <link name="panda_link1">
    <visual>
      <geometry>
        <mesh filename="file://$(find franka_description)/meshes/visual/link1.dae"/>
      </geometry>
    </visual>
    <collision>
      <geometry>
        <mesh filename="file://$(find franka_description)/meshes/collision/link1.stl"/>
      </geometry>
    </collision>
    <inertial>
      <origin rpy="0 0 0" xyz="0.003875 0.002081 -0.04762"/>
      <mass value="4.970684"/>
      <inertia ixx="0.70337" ixy="-0.000139" ixz="0.006772" iyy="0.70661" iyz="0.019169" izz="0.009117"/>
    </inertial>
  </link>
  <!-- sub-link defining coarse geometries of real robot's internal self-collision -->
  <link name="panda_link1_sc">
  </link>
  <!-- fixed joint between both sub-links -->
  <joint name="panda_link1_sc_joint" type="fixed">
    <origin rpy="0 0 0"/>
    <parent link="panda_link1"/>
    <child link="panda_link1_sc"/>
  </joint>
  <joint name="panda_joint1" type="revolute">
    <origin rpy="0 0 0" xyz="0 0 0.333"/>
    <parent link="panda_link0"/>
    <child link="panda_link1"/>
    <axis xyz="0 0 1"/>
    <limit effort="87.0" lower="-2.8973" upper="2.8973" velocity="2.175"/>
    <safety_controller k_position="100.0" k_velocity="40.0" soft_lower_limit="-2.8973" soft_upper_limit="2.8973"/>
    <dynamics D="1" K="7000" damping="0.003" friction="0.0" mu_coulomb="0" mu_viscous="16"/>
  </joint>
  <!-- sub-link defining detailed meshes for collision with environment -->
  <link name="panda_link2">
    <visual>
      <geometry>
        <mesh filename="file://$(find franka_description)/meshes/visual/link2.dae"/>
      </geometry>
    </visual>
    <collision>
      <geometry>
        <mesh filename="file://$(find franka_description)/meshes/collision/link2.stl"/>
      </geometry>
    </collision>
    <inertial>
      <origin rpy="0 0 0" xyz="-0.003141 -0.02872  0.003495"/>
      <mass value="0.646926"/>
      <inertia ixx="0.007962" ixy="-0.003925" ixz="0.010254" iyy="0.02811" iyz="0.000704" izz="0.025995"/>
    </inertial>
  </link>
  <!-- sub-link defining coarse geometries of real robot's internal self-collision -->
  <link name="panda_link2_sc">
  </link>
  <!-- fixed joint between both sub-links -->
  <joint name="panda_link2_sc_joint" type="fixed">
    <origin rpy="0 0 0"/>
    <parent link="panda_link2"/>
    <child link="panda_link2_sc"/>
  </joint>
  <joint name="panda_joint2" type="revolute">
    <origin rpy="-1.5707963267948966 0 0" xyz="0 0 0"/>
    <parent link="panda_link1"/>
    <child link="panda_link2"/>
    <axis xyz="0 0 1"/>
    <limit effort="87.0" lower="-1.7628" upper="1.7628" velocity="2.175"/>
    <safety_controller k_position="100.0" k_velocity="40.0" soft_lower_limit="-1.7628" soft_upper_limit="1.7628"/>
    <dynamics D="1" K="7000" damping="0.003" friction="0.0" mu_coulomb="0" mu_viscous="16"/>
  </joint>
  <!-- sub-link defining detailed meshes for collision with environment -->
  <link name="panda_link3">
    <visual>
      <geometry>
        <mesh filename="file://$(find franka_description)/meshes/visual/link3.dae"/>
      </geometry>
    </visual>
    <collision>
      <geometry>
        <mesh filename="file://$(find franka_description)/meshes/collision/link3.stl"/>
      </geometry>
    </collision>
    <inertial>
      <origin rpy="0 0 0" xyz="2.7518e-02 3.9252e-02 -6.6502e-02"/>
      <mass value="3.228604"/>
      <inertia ixx="0.037242" ixy="-0.004761" ixz="-0.011396" iyy="0.036155" iyz="-0.012805" izz="0.01083"/>
    </inertial>
  </link>
  <!-- sub-link defining coarse geometries of real robot's internal self-collision -->
  <link name="panda_link3_sc">
  </link>
  <!-- fixed joint between both sub-links -->
  <joint name="panda_link3_sc_joint" type="fixed">
    <origin rpy="0 0 0"/>
    <parent link="panda_link3"/>
    <child link="panda_link3_sc"/>
  </joint>
  <joint name="panda_joint3" type="revolute">
    <origin rpy="1.5707963267948966 0 0" xyz="0 -0.316 0"/>
    <parent link="panda_link2"/>
    <child link="panda_link3"/>
    <axis xyz="0 0 1"/>
    <limit effort="87.0" lower="-2.8973" upper="2.8973" velocity="2.175"/>
    <safety_controller k_position="100.0" k_velocity="40.0" soft_lower_limit="-2.8973" soft_upper_limit="2.8973"/>
    <dynamics D="1" K="7000" damping="0.003" friction="0.0" mu_coulomb="0" mu_viscous="16"/>
  </joint>
  <!-- sub-link defining detailed meshes for collision with environment -->
  <link name="panda_link4">
    <visual>
      <geometry>
        <mesh filename="file://$(find franka_description)/meshes/visual/link4.dae"/>
      </geometry>
    </visual>
    <collision>
      <geometry>
        <mesh filename="file://$(find franka_description)/meshes/collision/link4.stl"/>
      </geometry>
    </collision>
    <inertial>
      <origin rpy="0 0 0" xyz="-5.317e-02 1.04419e-01 2.7454e-02"/>
      <mass value="3.587895"/>
      <inertia ixx="0.025853" ixy="0.007796" ixz="-0.001332" iyy="0.019552" iyz="0.008641" izz="0.028323"/>
    </inertial>
  </link>
  <!-- sub-link defining coarse geometries of real robot's internal self-collision -->
  <link name="panda_link4_sc">
  </link>
  <!-- fixed joint between both sub-links -->
  <joint name="panda_link4_sc_joint" type="fixed">
    <origin rpy="0 0 0"/>
    <parent link="panda_link4"/>
    <child link="panda_link4_sc"/>
  </joint>
  <joint name="panda_joint4" type="revolute">
    <origin rpy="1.5707963267948966 0 0" xyz="0.0825 0 0"/>
    <parent link="panda_link3"/>
    <child link="panda_link4"/>
    <axis xyz="0 0 1"/>
    <limit effort="87.0" lower="-3.0718" upper="-0.0698" velocity="2.175"/>
    <safety_controller k_position="100.0" k_velocity="40.0" soft_lower_limit="-3.0718" soft_upper_limit="-0.0698"/>
    <dynamics D="1" K="7000" damping="0.003" friction="0.0" mu_coulomb="0" mu_viscous="16"/>
  </joint>
  <!-- sub-link defining detailed meshes for collision with environment -->
  <link name="panda_link5">
    <visual>
      <geometry>
        <mesh filename="file://$(find franka_description)/meshes/visual/link5.dae"/>
      </geometry>
    </visual>
    <collision>
      <geometry>
        <mesh filename="file://$(find franka_description)/meshes/collision/link5.stl"/>
      </geometry>
    </collision>
    <inertial>
      <origin rpy="0 0 0" xyz="-1.1953e-02 4.1065e-02 -3.8437e-02"/>
      <mass value="1.225946"/>
      <inertia ixx="0.035549" ixy="-0.002117" ixz="-0.004037" iyy="0.029474" iyz="0.000229" izz="0.008627"/>
    </inertial>
  </link>
  <!-- sub-link defining coarse geometries of real robot's internal self-collision -->
  <link name="panda_link5_sc">
  </link>
  <!-- fixed joint between both sub-links -->
  <joint name="panda_link5_sc_joint" type="fixed">
    <origin rpy="0 0 0"/>
    <parent link="panda_link5"/>
    <child link="panda_link5_sc"/>
  </joint>
  <joint name="panda_joint5" type="revolute">
    <origin rpy="-1.5707963267948966 0 0" xyz="-0.0825 0.384 0"/>
    <parent link="panda_link4"/>
    <child link="panda_link5"/>
    <axis xyz="0 0 1"/>
    <limit effort="12.0" lower="-2.8973" upper="2.8973" velocity="2.61"/>
    <safety_controller k_position="100.0" k_velocity="40.0" soft_lower_limit="-2.8973" soft_upper_limit="2.8973"/>
    <dynamics D="1" K="7000" damping="0.003" friction="0.0" mu_coulomb="0" mu_viscous="16"/>
  </joint>
  <!-- sub-link defining detailed meshes for collision with environment -->
  <link name="panda_link6">
    <visual>
      <geometry>
        <mesh filename="file://$(find franka_description)/meshes/visual/link6.dae"/>
      </geometry>
    </visual>
    <collision>
      <geometry>
        <mesh filename="file://$(find franka_description)/meshes/collision/link6.stl"/>
      </geometry>
    </collision>
    <inertial>
      <origin rpy="0 0 0" xyz="6.0149e-02 -1.4117e-02 -1.0517e-02"/>
      <mass value="1.666555"/>
      <inertia ixx="0.001964" ixy="0.000109" ixz="-0.001158" iyy="0.004354" iyz="0.000341" izz="0.005433"/>
    </inertial>
  </link>
  <!-- sub-link defining coarse geometries of real robot's internal self-collision -->
  <link name="panda_link6_sc">
  </link>
  <!-- fixed joint between both sub-links -->
  <joint name="panda_link6_sc_joint" type="fixed">
    <origin rpy="0 0 0"/>
    <parent link="panda_link6"/>
    <child link="panda_link6_sc"/>
  </joint>
  <joint name="panda_joint6" type="revolute">
    <origin rpy="1.5707963267948966 0 0" xyz="0 0 0"/>
    <parent link="panda_link5"/>
    <child link="panda_link6"/>
    <axis xyz="0 0 1"/>
    <limit effort="12.0" lower="-0.0175" upper="3.7525" velocity="2.61"/>
    <safety_controller k_position="100.0" k_velocity="40.0" soft_lower_limit="-0.0175" soft_upper_limit="3.7525"/>
    <dynamics D="1" K="7000" damping="0.003" friction="0.0" mu_coulomb="0" mu_viscous="16"/>
  </joint>
  <!-- sub-link defining detailed meshes for collision with environment -->
  <link name="panda_link7">
    <visual>
      <geometry>
        <mesh filename="file://$(find franka_description)/meshes/visual/link7.dae"/>
      </geometry>
    </visual>
    <collision>
      <geometry>
        <mesh filename="file://$(find franka_description)/meshes/collision/link7.stl"/>
      </geometry>
    </collision>
    <inertial>
      <origin rpy="0 0 0" xyz="1.0517e-02 -4.252e-03 6.1597e-02"/>
      <mass value="0.735522"/>
      <inertia ixx="0.012516" ixy="-0.000428" ixz="-0.001196" iyy="0.010027" iyz="-0.000741" izz="0.004815"/>
    </inertial>
  </link>
  <!-- sub-link defining coarse geometries of real robot's internal self-collision -->
  <link name="panda_link7_sc">
  </link>
  <!-- fixed joint between both sub-links -->
  <joint name="panda_link7_sc_joint" type="fixed">
    <origin rpy="0 0 0.7853981633974483"/>
    <parent link="panda_link7"/>
    <child link="panda_link7_sc"/>
  </joint>
  <joint name="panda_joint7" type="revolute">
    <origin rpy="1.5707963267948966 0 0" xyz="0.088 0 0"/>
    <parent link="panda_link6"/>
    <child link="panda_link7"/>
    <axis xyz="0 0 1"/>
    <limit effort="12.0" lower="-2.8973" upper="2.8973" velocity="2.61"/>
    <safety_controller k_position="100.0" k_velocity="40.0" soft_lower_limit="-2.8973" soft_upper_limit="2.8973"/>
    <dynamics D="1" K="7000" damping="0.003" friction="0.0" mu_coulomb="0" mu_viscous="16"/>
  </joint>
  <link name="panda_link8"/>
  <joint name="panda_joint8" type="fixed">
    <origin rpy="0 0 0" xyz="0 0 0.107"/>
    <parent link="panda_link7"/>
    <child link="panda_link8"/>
  </joint>
  <joint name="panda_hand_joint" type="fixed">
    <parent link="panda_link8"/>
    <child link="panda_hand"/>
    <origin rpy="0 0 -0.7853981633974483" xyz="0 0 0"/>
  </joint>
  <!-- sub-link defining detailed meshes for collision with environment -->
  <link name="panda_hand">
    <visual>
      <geometry>
        <mesh filename="file://$(find franka_description)/meshes/visual/hand.dae"/>
      </geometry>
    </visual>
    <collision>
      <geometry>
        <mesh filename="file://$(find franka_description)/meshes/collision/hand.stl"/>
      </geometry>
    </collision>
    <inertial>
      <origin rpy="0 0 0" xyz="-0.01 0 0.03"/>
      <mass value="0.73"/>
      <inertia ixx="0.001" ixy="0" ixz="0" iyy="0.0025" iyz="0" izz="0.0017"/>
    </inertial>
  </link>
  <!-- sub-link defining coarse geometries of real robot's internal self-collision -->
  <link name="panda_hand_sc">
  </link>
  <!-- fixed joint between both sub-links -->
  <joint name="panda_hand_sc_joint" type="fixed">
    <origin rpy="0 0 0"/>
    <parent link="panda_hand"/>
    <child link="panda_hand_sc"/>
  </joint>
  <!-- Define the hand_tcp frame -->
  <link name="panda_hand_tcp"/>
  <joint name="panda_hand_tcp_joint" type="fixed">
    <origin rpy="0 0 0" xyz="0 0 0.1034"/>
    <parent link="panda_hand"/>
    <child link="panda_hand_tcp"/>
  </joint>
  <link name="panda_leftfinger">
    <visual>
      <geometry>
        <mesh filename="file://$(find franka_description)/meshes/visual/finger.dae"/>
      </geometry>
    </visual>
    <!-- screw mount -->
    <collision>
      <origin rpy="0 0 0" xyz="0 18.5e-3 11e-3"/>
      <geometry>
        <box size="22e-3 15e-3 20e-3"/>
      </geometry>
    </collision>
    <!-- cartriage sledge -->
    <collision>
      <origin rpy="0 0 0" xyz="0 6.8e-3 2.2e-3"/>
      <geometry>
        <box size="22e-3 8.8e-3 3.8e-3"/>
      </geometry>
    </collision>
    <!-- diagonal finger -->
    <collision>
      <origin rpy="0.5235987755982988 0 0" xyz="0 15.9e-3 28.35e-3"/>
      <geometry>
        <box size="17.5e-3 7e-3 23.5e-3"/>
      </geometry>
    </collision>
    <!-- rubber tip with which to grasp -->
    <collision>
      <origin rpy="0 0 0" xyz="0 7.58e-3 45.25e-3"/>
      <geometry>
        <box size="17.5e-3 15.2e-3 18.5e-3"/>
      </geometry>
    </collision>
    <inertial>
      <origin rpy="0 0 0" xyz="0 0 0"/>
      <mass value="0.015"/>
      <inertia ixx="2.3749999999999997e-06" ixy="0" ixz="0" iyy="2.3749999999999997e-06" iyz="0" izz="7.5e-07"/>
    </inertial>
  </link>
  <link name="panda_rightfinger">
    <visual>
      <origin rpy="0 0 3.141592653589793" xyz="0 0 0"/>
      <geometry>
        <mesh filename="file://$(find franka_description)/meshes/visual/finger.dae"/>
      </geometry>
    </visual>
    <!-- screw mount -->
    <collision>
      <origin rpy="0 0 0" xyz="0 -18.5e-3 11e-3"/>
      <geometry>
        <box size="22e-3 15e-3 20e-3"/>
      </geometry>
    </collision>
    <!-- cartriage sledge -->
    <collision>
      <origin rpy="0 0 0" xyz="0 -6.8e-3 2.2e-3"/>
      <geometry>
        <box size="22e-3 8.8e-3 3.8e-3"/>
      </geometry>
    </collision>
    <!-- diagonal finger -->
    <collision>
      <origin rpy="-0.5235987755982988 0 0" xyz="0 -15.9e-3 28.35e-3"/>
      <geometry>
        <box size="17.5e-3 7e-3 23.5e-3"/>
      </geometry>
    </collision>
    <!-- rubber tip with which to grasp -->
    <collision>
      <origin rpy="0 0 0" xyz="0 -7.58e-3 45.25e-3"/>
      <geometry>
        <box size="17.5e-3 15.2e-3 18.5e-3"/>
      </geometry>
    </collision>
    <inertial>
      <origin rpy="0 0 0" xyz="0 0 0"/>
      <mass value="0.015"/>
      <inertia ixx="2.3749999999999997e-06" ixy="0" ixz="0" iyy="2.3749999999999997e-06" iyz="0" izz="7.5e-07"/>
    </inertial>
  </link>
  <joint name="panda_finger_joint1" type="prismatic">
    <parent link="panda_hand"/>
    <child link="panda_leftfinger"/>
    <origin rpy="0 0 0" xyz="0 0 0.0584"/>
    <axis xyz="0 1 0"/>
    <limit effort="100" lower="0.0" upper="0.04" velocity="0.2"/>
    <dynamics damping="0.3"/>
  </joint>
  <joint name="panda_finger_joint2" type="prismatic">
    <parent link="panda_hand"/>
    <child link="panda_rightfinger"/>
    <origin rpy="0 0 0" xyz="0 0 0.0584"/>
    <axis xyz="0 -1 0"/>
    <limit effort="100" lower="0.0" upper="0.04" velocity="0.2"/>
    <mimic joint="panda_finger_joint1"/>
    <dynamics damping="0.3"/>
  </joint>


  <!-- <link name="world"/>
  <joint name="world_joint" type="fixed">
    <origin rpy="0 0 0" xyz="0 0 0"/>
    <parent link="world"/>
    <child link="panda_link0"/>
  </joint> -->


  <!-- CAMERA  LINK -->
      <joint name="camera_joint" type="fixed">
        <parent link="mobile_base_link"/>
        <child link="camera_link"/>
        <origin xyz="0.35 0.0 1.5" rpy="0 1.57 0"/>
    </joint>

    <link name="camera_link">
        <visual>
            <geometry>
                <box size="0.010 0.03 0.03"/>
            </geometry>
            <!-- <material name="red"/> -->
        </visual>
    </link>


    <joint name="camera_optical_joint" type="fixed">
        <parent link="camera_link"/>
        <child link="camera_link_optical"/>
        <origin xyz="0 0 0" rpy="${-pi/2} 0 ${-pi/2}"/>
    </joint>

    <link name="camera_link_optical"></link>

    <gazebo reference="camera_link">
        <!-- <material>Gazebo/Silver</material> -->

        <sensor name="camera" type="depth">
            <pose> 0 0 0 0 0 0 </pose>
            <visualize>true</visualize>
            <update_rate>10</update_rate>
            <camera>
                <horizontal_fov>1.089</horizontal_fov>
                <image>
                    <format>B8G8R8</format>
                    <width>640</width>
                    <height>480</height>
                </image>
                <clip>
                    <near>0.05</near>
                    <far>8.0</far>
                </clip>
            </camera>
            <plugin name="camera_controller" filename="libgazebo_ros_camera.so">
                <frame_name>camera_link_optical</frame_name>
                <min_depth>0.1</min_depth>
                <max_depth>100.0</max_depth>
            </plugin>
        </sensor>
    </gazebo>
  <!--  -->
  

  <!-- adding ros2 controller -->
  <ros2_control name="GazeboSystem" type="system">
    <hardware>
        <!-- By default, set up controllers for simulation. This won't work on real hardware -->
        <plugin>gazebo_ros2_control/GazeboSystem</plugin>
    </hardware>
    <joint name="panda_joint1">
        <command_interface name="position"/>
        <state_interface name="position">
          <param name="initial_value">0</param>
        </state_interface>
        <state_interface name="velocity"/>
    </joint>
    <joint name="panda_joint2">
        <command_interface name="position"/>
        <state_interface name="position">
          <param name="initial_value">0</param>
        </state_interface>
        <state_interface name="velocity"/>
    </joint>
    <joint name="panda_joint3">
        <command_interface name="position"/>
        <state_interface name="position">
          <param name="initial_value">0</param>
        </state_interface>
        <state_interface name="velocity"/>
    </joint>
    <joint name="panda_joint4">
        <command_interface name="position"/>
        <state_interface name="position">
          <param name="initial_value">0</param>
        </state_interface>
        <state_interface name="velocity"/>
    </joint>
    <joint name="panda_joint5">
        <command_interface name="position"/>
        <state_interface name="position">
          <param name="initial_value">0</param>
        </state_interface>
        <state_interface name="velocity"/>
    </joint>
    <joint name="panda_joint6">
        <command_interface name="position"/>
        <state_interface name="position">
          <param name="initial_value">0</param>
        </state_interface>
        <state_interface name="velocity"/>
    </joint>
    <joint name="panda_joint7">
        <command_interface name="position"/>
        <state_interface name="position">
          <param name="initial_value">0</param>
        </state_interface>
        <state_interface name="velocity"/>
    </joint>
    <joint name="panda_finger_joint1">
        <command_interface name="position"/>
        <state_interface name="position">
          <param name="initial_value">0</param>
        </state_interface>
        <state_interface name="velocity"/>
    </joint>
    <joint name="front_left_wheel_joint">
          <command_interface name="velocity">
              <param name="min">-10</param>
              <param name="max">10</param>
          </command_interface>
          <state_interface name="position"/>
          <state_interface name="velocity"/>
      </joint>
    <joint name="rear_left_wheel_joint">
          <command_interface name="velocity">
              <param name="min">-10</param>
              <param name="max">10</param>
          </command_interface>
          <state_interface name="position"/>
          <state_interface name="velocity"/>
      </joint>
    <joint name="front_right_wheel_joint">
          <command_interface name="velocity">
              <param name="min">-10</param>
              <param name="max">10</param>
          </command_interface>
          <state_interface name="position"/>
          <state_interface name="velocity"/>
      </joint>
      <joint name="rear_right_wheel_joint">
          <command_interface name="velocity">
              <param name="min">-10</param>
              <param name="max">10</param>
          </command_interface>
          <state_interface name="position"/>
          <state_interface name="velocity"/>
      </joint>


  </ros2_control>

  
  <!-- <gazebo>
    <plugin filename="libgazebo_ros2_control.so" name="gazebo_ros2_control">
      <robot_param>robot_description</robot_param>
      <robot_param_node>robot_state_publisher</robot_param_node>
      <parameters>/home/fudhail/udemy_ws/src/franka_gazebo/config/ros2_controller.yaml</parameters>
    </plugin>
  </gazebo> -->
  <gazebo>
    <plugin filename="libgazebo_ros2_control.so" name="gazebo_ros2_control">
        <robot_param>robot_description</robot_param>
        <robot_param_node>robot_state_publisher</robot_param_node>
        <parameters>/home/fudhail/project_ws/src/ros2_moveit2/franka_gazebo/config/ros2_controller.yaml</parameters>
    </plugin>
</gazebo>


</robot>
